<mujoco>

    <compiler angle="radian"/>

    <option gravity="0 0 0" cone="elliptic" timestep="0.02" />

    <size njmax="500" nconmax="100" />

    <visual>
        <map znear="0.001" />
        <headlight active="1"/>
    </visual>

    <default>
        <light castshadow="false" diffuse="1 1 1" />
        <joint frictionloss="1" damping="1" />
        <camera fovy="60" />
        <motor gear="0.8"/>
        <velocity kv="10"/>
        <position kp="5"/>
    </default>
    
    

    <asset>
        <mesh file="ur5/base.stl" />
        <mesh file="ur5/shoulder.stl" />
        <mesh file="ur5/upperarm.stl" />
        <mesh file="ur5/forearm.stl" />
        <mesh file="ur5/wrist1.stl" />
        <mesh file="ur5/wrist2.stl" />
        <mesh file="ur5/wrist3.stl" />
        <mesh file="ur5/kinova_robotiq_coupler.stl" />
        <mesh file="ur5/robotiq_85_base_link.stl" />
        <mesh file="ur5/robotiq_85_finger_link.stl" />
        <mesh file="ur5/robotiq_85_finger_tip_link.stl" />
        <mesh file="ur5/robotiq_85_inner_knuckle_link.stl" />
        <mesh file="ur5/robotiq_85_knuckle_link.stl" />
        <material name="RobMat" specular="0.9" shininess="0.5" reflectance="0" rgba="0.7 0.7 0.7 1" emission="0.1" />
        <material name="GriMat" specular="0.9" shininess="0.5" reflectance="0" rgba="0.1 0.1 0.1 1" emission="0.1" />
        <material name="BasketMat" specular="0" shininess="0" reflectance="0" rgba="0.26 0.16 0.16796875 1" emission="0" />
        <material name="Light" specular="0" shininess="0.6" reflectance="0.9" rgba="0.5 0.5 1 1" emission="0.7" />
        
        <mesh file="objects/big_bolt.stl" scale="0.005 0.005 0.005"/>
        <mesh file="objects/big_nut.stl" scale="0.005 0.005 0.005"/>
    </asset>
    
   <worldbody>
        <!--body pos="-0.16 0.90 0.02" euler="4.71238898 0 3.14159265">
            <body euler="0 -0.82 0">
                <camera name="workbench_camera" euler="0.25 0 0" fovy="43" />
            </body>
        </body>
        <body pos="-1 1.52 0.64" euler="4.71238898 0 3.14159265">
            <body euler="-0.23 0 0">
                <camera name="upper_camera" euler="0 0.09 0" fovy="41" />
            </body>
        </body-->

        <!-- Lighting and furniture -->
        <light pos="0 0 3" castshadow="true" directional="true" dir="0 0 -1" />
        <geom name="floor" pos="0 0 0" quat="0 0 0 1" size="5 5 1" type="plane" rgba="1 0.83 0.61 1" material="BasketMat" />
        <geom name="table" pos="0.8 0 0.4" size="1 0.5 0.4" type="box" rgba="1 0.83 0.61 1" material="BasketMat"/>
        <geom name="stand" pos="0 0 0.9" size="0.1 0.1 0.1" type="box" rgba="1 0.83 0.61 1" material="BasketMat"/>

        <!-- UR5 and gripper -->
        <body name="base_link" pos="0 0 1" quat="1 0 0 0" >
            <inertial pos="0 0 0" quat="0.5 0.5 -0.5 0.5" mass="4" diaginertia="0.0072 0.00443333 0.00443333" />
            <geom name="base_mesh" type="mesh" mesh="base" material="RobMat" />
            <geom name="base_cap" type="cylinder" pos="0 0 0.14" size="0.06 0.02" rgba="0.596 0.96 1 1" material="RobMat" contype="0" conaffinity="0" />

            <body name="shoulder_link" pos="0 0 0.089159">
                <inertial pos="0 0 0" mass="3.7" diaginertia="0.0102675 0.0102675 0.00666" />
                <geom name="shoulder_mesh" type="mesh" mesh="shoulder" material="RobMat" />
                <geom name="shoulder_cap" type="cylinder" pos="0 0.185 0" quat="0.707107 0.707107 0 0" size="0.06 0.02" rgba="0.596 0.96 1 1" material="RobMat" contype="0" conaffinity="0" />
                <joint name="joint1" pos="0 0 0" axis="0 0 1" />

                <body name="upper_arm_link" pos="0 0.13585 0" quat="0.707107 0 0.707107 0">
                    <inertial pos="0 0 0.28" mass="8.393" diaginertia="0.226891 0.226891 0.0151074" />
                    <geom name="upperarm_mesh" type="mesh" mesh="upperarm" material="RobMat" />
                    <joint name="joint2" pos="0 0 0" axis="0 1 0" />

                    <body name="forearm_link" pos="0 -0.1197 0.425">
                        <inertial pos="0 0 0.25" mass="2.275" diaginertia="0.0494433 0.0494433 0.004095" />
                        <geom name="forearm_mesh" type="mesh" mesh="forearm" material="RobMat" />

                        <!--camera name="forearm_camera" pos="0 0.1 0.07" euler="3.14159265 0 1.570796" /-->

                        <geom name="forearm_cap" type="cylinder" pos="0 0.17 0" quat="0.707107 0.707107 0 0" size="0.06 0.02" rgba="0.596 0.96 1 1" material="RobMat" contype="0" conaffinity="0" />
                        <joint name="joint3" pos="0 0 0" axis="0 1 0" />

                        <body name="wrist1_link" pos="0 0 0.39225" quat="0.707107 0 0.707107 0">
                            <inertial pos="0 0 0" quat="0.5 0.5 -0.5 0.5" mass="1.219" diaginertia="0.21942 0.111173 0.111173" />
                            <geom name="wrist1_mesh" type="mesh" mesh="wrist1" material="RobMat" />
                            <geom name="wrist1_cap" type="cylinder" pos="0 -0.045 0" quat="0.707107 0.707107 0 0" size="0.04 0.015" rgba="0.596 0.96 1 1" material="RobMat" contype="0" conaffinity="0" />
                            <joint name="joint4" pos="0 0 0" axis="0 1 0" />

                            <body name="wrist2_link" pos="0 0.093 0">
                                <inertial pos="0 0 0" quat="0.5 0.5 -0.5 0.5" mass="1.219" diaginertia="0.21942 0.111173 0.111173" />
                                <geom name="wrist2_mesh" type="mesh" mesh="wrist2" material="RobMat" />
                                <geom name="wrist2_cap" type="cylinder" pos="0 0 -0.045" quat="0.707107 0 0 0.707107" size="0.04 0.015" rgba="0.596 0.96 1 1" material="RobMat" contype="0" conaffinity="0" />
                                <joint name="joint5" pos="0 0 0" axis="0 0 1" />

                                <body name="wrist3_link" pos="0 0 0.09465" quat="0.707107 0 -0.707107 0" >
                                    <inertial pos="0 0 0" quat="0.5 0.5 -0.5 0.5" mass="0.1879" diaginertia="0.033822 0.0171365 0.0171365" />
                                    <geom name="wrist3_mesh" type="mesh" mesh="wrist3" material="RobMat" contype="1" conaffinity="1" />
                                    <geom name="wrist3_cap" type="cylinder" pos="0 -0.045 0" quat="0.707107 0.707107 0 0" size="0.04 0.015" rgba="0.596 0.96 1 1" material="RobMat" contype="0" conaffinity="0" />
                                    <joint name="joint6" pos="0 0 0" axis="0 1 0" />

                                    <body name="ee_link" pos="0 0.0823 0" quat="0.707107 -0.707107 0 0">
                                        <inertial pos="0 0.0823 0" quat="0.707107 -0.707107 0 0" mass="0" diaginertia="0 0 0" />

                                        <!--camera name="gripper_camera" euler="0 3.14159265 0" fovy="63.5" />
                                        <geom name="light_1" type="sphere" size="0.005" pos="0.035 0 0.0166" material="Light" />
                                        <geom name="light_2" type="sphere" size="0.005" pos="-0.035 0 0.0166" material="Light" /-->
                                        <geom name="kinova_robotiq_coupler_mesh" type="mesh" mesh="kinova_robotiq_coupler" pos="0 0 0.0466" material="GriMat" />
                                        <geom name="robotiq_85_base_link_mesh" type="mesh" mesh="robotiq_85_base_link" pos="0 0 0.0016" quat="0.707107 0 -0.707107 0" material="GriMat" />

                                        <body name="right_driver" pos="0 -0.0306011 0.054904" quat="0.707107 0 -0.707107 0">
                                            <geom name="right_driver_mesh" type="mesh" mesh="robotiq_85_knuckle_link" material="GriMat" contype="0" conaffinity="0" />
                                            <joint name="joint7_1" axis="0 0 1" type="hinge" limited="true" range="0 0.872664626" />

                                        
                                            <body name="right_coupler" pos="0 -0.0315 0">
                                                <geom name="right_coupler_mesh" type="mesh" mesh="robotiq_85_finger_link" material="GriMat" contype="0" conaffinity="0" />
                                                <joint name="joint8_1" axis="0 0 1" type="hinge" limited="true" range="0 2.967059728" />

                                                <body name="right_follower_link" pos="0.0475 -0.006 0">
                                                    <geom name="right_follower_mesh" pos="0.0025 0.021 0" type="mesh" mesh="robotiq_85_finger_tip_link" material="GriMat" />
                                                    <joint name="joint9_1" axis="0 0 1" type="hinge" limited="true" range="0 2.967059728" />
                                                </body>

                                            </body>

                                        </body>

                                        <body name="right_spring_link" pos="0.0016 -0.012 0.0614" quat="0.707107 0 -0.707107 0">
                                            <geom name="right_spring_mesh" type="mesh" pos="0 -0.0005 0.0016" mesh="robotiq_85_inner_knuckle_link" material="GriMat" contype="0" conaffinity="0" />
                                            <joint name="joint10_1" axis="0 0 1" type="hinge" limited="true" range="0 1" />
                                        </body>


                                        <body name="left_driver" pos="0 0.0306011 0.054904" quat="0 0.707107 0 0.707107">
                                            <geom name="left_driver_mesh" type="mesh" mesh="robotiq_85_knuckle_link" material="GriMat" contype="0" conaffinity="0" />
                                            <joint name="joint7_2" axis="0 0 1" type="hinge" limited="true" range="0 0.872664626" />

                                        
                                            <body name="left_coupler" pos="0 -0.0315 0">
                                                <geom name="left_coupler_mesh" type="mesh" mesh="robotiq_85_finger_link" material="GriMat" contype="0" conaffinity="0" />
                                                <joint name="joint8_2" axis="0 0 1" type="hinge" limited="true" range="0 2.967059728" />

                                                <body name="left_follower_link" pos="0.0475 -0.006 0">
                                                    <geom name="left_follower_mesh" pos="0.0025 0.021 0" type="mesh" mesh="robotiq_85_finger_tip_link" material="GriMat" />
                                                    <joint name="joint9_2" axis="0 0 1" type="hinge" limited="true" range="0 2.967059728" />
                                                </body>

                                            </body>

                                        </body>

                                        <body name="left_spring_link" pos="0.0016 0.012 0.0614" quat="0 0.707107 0 0.707107">
                                            <geom name="left_spring_mesh" type="mesh" pos="0 0.0005 0.0016" mesh="robotiq_85_inner_knuckle_link" material="GriMat" contype="0" conaffinity="0" />
                                            <joint name="joint10_2" axis="0 0 1" type="hinge" limited="true" range="0 1" />
                                        </body>

                                    </body>
                                </body>
                            </body>
                        </body>
                    </body>
                </body>
            </body>
        </body>
        
        <!-- Other scene objects -->
        <geom name="bolt" pos="0.8 -0.2 0.875" quat="0 0 1 0" type="mesh" mesh="big_bolt" material="RobMat"/>
        <geom name="nut" pos="0.8 0.2 0.8" type="mesh" mesh="big_nut" material="RobMat"/>

   </worldbody>

    <actuator>
        <!-- gripper driver torque control -->
        <motor name="close_1" joint="joint7_1" gear="0.2 0 0 0 0 0" />
        <motor name="close_2" joint="joint7_2" gear="0.2 0 0 0 0 0" />

    </actuator>
    
    <sensor>

    </sensor>
    
</mujoco>
