<mujoco>

    <compiler angle="radian" />

    <size njmax="500" nconmax="100" />

    <visual>
        <map znear="0.001" />
        <headlight active="1"/>
    </visual>

    <default>
        <geom contype='1' conaffinity='1' condim='4'  margin="1e-3" solref=".01 1" solimp=".99 .99 .01" />
        <light castshadow="false" diffuse="1 1 1" />
        <camera fovy="60" />
        <motor gear="0.8"/>
        <velocity kv="10"/>
        <position kp="5"/>
    </default>
    
    

    <!-- UR5 + gripper -->
    <include file="ur5/ur5.xml"/>
    
    

    <asset>
        <texture name="metal"        type="cube"     file="textures/metal1.png"/>
        <material name="BenchMat"      texture="metal"   shininess="1.0" specular="0.5" reflectance="0.2"/>
        <texture name="floor_tex"   type="2d"        builtin="checker" rgb1=".2 .3 .4" rgb2=".1 .2 .3" width="100" height="100" />
        <material name="floor_mat"      texture="floor_tex"  shininess="0.8" texrepeat="10 10" specular="0.7"  reflectance="0.5" />
        <material name="WallMat" specular="0.5" shininess="0.6" reflectance="0.9" rgba="0.1 0.1 0.1 1" emission="1" />
        
        <material name="BaseMat" specular="0" shininess="0.6" reflectance="0.9" rgba="0.5 0 0 1" emission="0" />
        <material name="ShaftMat" specular="0" shininess="0.6" reflectance="0.9" rgba="0.2 0.2 0.2 1" emission="0" />
        <material name="NutMat" specular="0" shininess="0.6" reflectance="0.9" rgba="0.7 0.7 0.7 1" emission="0" />

        <mesh file="objects/nut.stl" scale="0.001 0.001 0.001"/>
        <mesh file="objects/shaft_rot.stl" scale="0.001 0.001 0.001"/>
    </asset>
    
    <worldbody>
        <!-- lights -->
        <light pos="0.3 0 2" directional="false" dir="0 0 -1" />
        <!-- furniture -->
        <geom name="floor" pos="2 0 -1" quat="0 0 0 1" size="5 5 1" type="plane" rgba="1 0.83 0.61 1" material="floor_mat" />
        <geom name="wall_l" pos="0.3 -0.5 0" euler="1.5708 3.1416 0" size="0.5 1.0 1" type="plane" material="WallMat" contype='0' conaffinity='0'/>
        <geom name="wall_r" pos="0.3 0.5 0" euler="1.5708 0 0" size="0.5 1.0 1" type="plane" material="WallMat" contype='0' conaffinity='0'/>
        <geom name="wall_b" pos="-0.2 0 0" euler="1.5708 1.5708 0" size="0.5 1.0 1" type="plane" material="WallMat" contype='0' conaffinity='0'/>
        <geom name="table" pos="0.3 0 -0.0025" size="0.4 0.4 0.005" type="box" material="BenchMat"/>
        
        <!-- ROS camera -->        
        <body pos="1.120951 -0.015672 0.335584" euler="-0.042834 -0.267927 -3.119534"> <!-- rotations *= -1 ? -->
            <camera name="ros_cam" euler="-1.5708 -1.5708 0" fovy="43.3" />
        </body>

        <!-- manip objects -->
        <body name="base" pos="0.54 -0.2 0.01">
            <geom name="base_geom" size="0.075 0.045 0.0075" type="box" material="BaseMat"/>
<!--            <joint type="free"/>-->
            <joint name="base_tx" type="slide" axis="1 0 0"/>
            <joint name="base_ty" type="slide" axis="0 1 0"/>
            <joint name="base_tz" type="slide" axis="0 0 1"/>
            <joint name="base_rx" type="hinge" axis="1 0 0"/>
            <joint name="base_ry" type="hinge" axis="0 1 0"/>
            <joint name="base_rz" type="hinge" axis="0 0 1"/>
            
            <body name="shaft" pos="0.04 0 0.07">
                <geom name="shaft_geom" pos="0 0 -0.062" euler="0 0 0" type="mesh" mesh="shaft_rot" material="ShaftMat" contype='0' conaffinity='0'/>
                
                <body name="nut" pos="-0.04 0.4 -0.06" euler="0 0 0">
                    <geom name="nut_geom" type="mesh" mesh="nut" material="NutMat"/>
                    <joint name="nut_tx" type="slide" axis="1 0 0"/>
                    <joint name="nut_ty" type="slide" axis="0 1 0"/>
                    <joint name="nut_tz" type="slide" axis="0 0 1"/>
                    <joint name="nut_rx" type="hinge" axis="1 0 0"/>
                    <joint name="nut_ry" type="hinge" axis="0 1 0"/>
                    <joint name="nut_rz" type="hinge" axis="0 0 1"/>
                </body>
            </body>
        </body>     
    </worldbody>

</mujoco>
